<sdf version='1.7'>
  <world name='CRANE-X7 with Table'>
    <scene>
      <shadows>0</shadows>
      <ambient>0.4 0.4 0.4 1</ambient>
      <background>0.7 0.7 0.7 1</background>
    </scene>
    <light name='sun' type='directional'>
      <cast_shadows>1</cast_shadows>
      <pose>0 0 10 0 -0 0</pose>
      <diffuse>0.8 0.8 0.8 1</diffuse>
      <specular>0.2 0.2 0.2 1</specular>
      <attenuation>
        <range>1000</range>
        <constant>0.9</constant>
        <linear>0.01</linear>
        <quadratic>0.001</quadratic>
      </attenuation>
      <direction>-0.5 0.1 -0.9</direction>
      <spot>
        <inner_angle>0</inner_angle>
        <outer_angle>0</outer_angle>
        <falloff>0</falloff>
      </spot>
    </light>
    <model name='table'>
      <frame name='table::__model__' attached_to='table::link'>
        <pose relative_to='__model__'>0 0 0 0 -0 0</pose>
      </frame>
      <static>1</static>
      <link name='table::link'>
        <collision name='surface'>
          <pose>0 0 1 0 -0 0</pose>
          <geometry>
            <box>
              <size>1.5 0.8 0.03</size>
            </box>
          </geometry>
          <surface>
            <friction>
              <ode>
                <mu>0.6</mu>
                <mu2>0.6</mu2>
              </ode>
              <torsional>
                <ode/>
              </torsional>
            </friction>
            <contact>
              <ode/>
            </contact>
            <bounce/>
          </surface>
          <max_contacts>10</max_contacts>
        </collision>
        <visual name='visual1'>
          <pose>0 0 1 0 -0 0</pose>
          <geometry>
            <box>
              <size>1.5 0.8 0.03</size>
            </box>
          </geometry>
          <material>
            <script>
              <uri>file://media/materials/scripts/gazebo.material</uri>
              <name>Gazebo/Wood</name>
            </script>
          </material>
        </visual>
        <collision name='front_left_leg'>
          <pose>0.68 0.38 0.5 0 -0 0</pose>
          <geometry>
            <cylinder>
              <radius>0.02</radius>
              <length>1</length>
            </cylinder>
          </geometry>
          <max_contacts>10</max_contacts>
          <surface>
            <contact>
              <ode/>
            </contact>
            <bounce/>
            <friction>
              <torsional>
                <ode/>
              </torsional>
              <ode/>
            </friction>
          </surface>
        </collision>
        <visual name='front_left_leg'>
          <pose>0.68 0.38 0.5 0 -0 0</pose>
          <geometry>
            <cylinder>
              <radius>0.02</radius>
              <length>1</length>
            </cylinder>
          </geometry>
          <material>
            <script>
              <uri>file://media/materials/scripts/gazebo.material</uri>
              <name>Gazebo/Grey</name>
            </script>
          </material>
        </visual>
        <collision name='front_right_leg'>
          <pose>0.68 -0.38 0.5 0 -0 0</pose>
          <geometry>
            <cylinder>
              <radius>0.02</radius>
              <length>1</length>
            </cylinder>
          </geometry>
          <max_contacts>10</max_contacts>
          <surface>
            <contact>
              <ode/>
            </contact>
            <bounce/>
            <friction>
              <torsional>
                <ode/>
              </torsional>
              <ode/>
            </friction>
          </surface>
        </collision>
        <visual name='front_right_leg'>
          <pose>0.68 -0.38 0.5 0 -0 0</pose>
          <geometry>
            <cylinder>
              <radius>0.02</radius>
              <length>1</length>
            </cylinder>
          </geometry>
          <material>
            <script>
              <uri>file://media/materials/scripts/gazebo.material</uri>
              <name>Gazebo/Grey</name>
            </script>
          </material>
        </visual>
        <collision name='back_right_leg'>
          <pose>-0.68 -0.38 0.5 0 -0 0</pose>
          <geometry>
            <cylinder>
              <radius>0.02</radius>
              <length>1</length>
            </cylinder>
          </geometry>
          <max_contacts>10</max_contacts>
          <surface>
            <contact>
              <ode/>
            </contact>
            <bounce/>
            <friction>
              <torsional>
                <ode/>
              </torsional>
              <ode/>
            </friction>
          </surface>
        </collision>
        <visual name='back_right_leg'>
          <pose>-0.68 -0.38 0.5 0 -0 0</pose>
          <geometry>
            <cylinder>
              <radius>0.02</radius>
              <length>1</length>
            </cylinder>
          </geometry>
          <material>
            <script>
              <uri>file://media/materials/scripts/gazebo.material</uri>
              <name>Gazebo/Grey</name>
            </script>
          </material>
        </visual>
        <collision name='back_left_leg'>
          <pose>-0.68 0.38 0.5 0 -0 0</pose>
          <geometry>
            <cylinder>
              <radius>0.02</radius>
              <length>1</length>
            </cylinder>
          </geometry>
          <max_contacts>10</max_contacts>
          <surface>
            <contact>
              <ode/>
            </contact>
            <bounce/>
            <friction>
              <torsional>
                <ode/>
              </torsional>
              <ode/>
            </friction>
          </surface>
        </collision>
        <visual name='back_left_leg'>
          <pose>-0.68 0.38 0.5 0 -0 0</pose>
          <geometry>
            <cylinder>
              <radius>0.02</radius>
              <length>1</length>
            </cylinder>
          </geometry>
          <material>
            <script>
              <uri>file://media/materials/scripts/gazebo.material</uri>
              <name>Gazebo/Grey</name>
            </script>
          </material>
        </visual>
        <pose relative_to='table::__model__'>0 0 0 0 -0 0</pose>
        <self_collide>0</self_collide>
        <enable_wind>0</enable_wind>
        <kinematic>0</kinematic>
      </link>
      <pose>0.29 0 0 0 -0 1.5708</pose>
    </model>
    <model name='ground_plane'>
      <frame name='ground_plane::__model__' attached_to='ground_plane::link'>
        <pose relative_to='__model__'>0 0 0 0 -0 0</pose>
      </frame>
      <static>1</static>
      <link name='ground_plane::link'>
        <collision name='collision'>
          <geometry>
            <plane>
              <normal>0 0 1</normal>
              <size>100 100</size>
            </plane>
          </geometry>
          <surface>
            <contact>
              <collide_bitmask>65535</collide_bitmask>
              <ode/>
            </contact>
            <friction>
              <ode>
                <mu>100</mu>
                <mu2>50</mu2>
              </ode>
              <torsional>
                <ode/>
              </torsional>
            </friction>
            <bounce/>
          </surface>
          <max_contacts>10</max_contacts>
        </collision>
        <visual name='visual'>
          <cast_shadows>0</cast_shadows>
          <geometry>
            <plane>
              <normal>0 0 1</normal>
              <size>100 100</size>
            </plane>
          </geometry>
          <material>
            <script>
              <uri>file://media/materials/scripts/gazebo.material</uri>
              <name>Gazebo/Grey</name>
            </script>
          </material>
        </visual>
        <pose relative_to='ground_plane::__model__'>0 0 0 0 -0 0</pose>
        <self_collide>0</self_collide>
        <enable_wind>0</enable_wind>
        <kinematic>0</kinematic>
      </link>
      <joint name='ground_joint' type='fixed'>
        <parent>ground_plane::link</parent>
        <child>table::link</child>
      </joint>
    </model>
    <gravity>0 0 -9.8</gravity>
    <magnetic_field>6e-06 2.3e-05 -4.2e-05</magnetic_field>
    <atmosphere type='adiabatic'/>
    <physics type='ode'>
      <max_step_size>0.001</max_step_size>
      <real_time_factor>1</real_time_factor>
      <real_time_update_rate>1000</real_time_update_rate>
    </physics>
    <wind/>
    <spherical_coordinates>
      <surface_model>EARTH_WGS84</surface_model>
      <latitude_deg>0</latitude_deg>
      <longitude_deg>0</longitude_deg>
      <elevation>0</elevation>
      <heading_deg>0</heading_deg>
    </spherical_coordinates>
    <state world_name='CRANE-X7 with Table'>
      <sim_time>15520 459000000</sim_time>
      <real_time>219 984310808</real_time>
      <wall_time>1634479527 501402043</wall_time>
      <iterations>218625</iterations>
      <model name='crane_x7'>
        <pose>0 0 1.02 0 -0 0</pose>
        <scale>1 1 1</scale>
        <link name='base_link'>
          <pose>0 0 1.02 0 -0 0</pose>
          <velocity>-0 0 -0 0 -0 0</velocity>
          <acceleration>0 -0 -0 3.6e-05 2.6e-05 1.3e-05</acceleration>
          <wrench>0 -0 -0 0 -0 0</wrench>
        </link>
        <link name='crane_x7_gripper_base_link'>
          <pose>0.000142 6e-06 1.644 -9e-06 0.006119 0.003017</pose>
          <velocity>0 0 0 0 0 -1e-06</velocity>
          <acceleration>0 -0 0 2.35515 0.05087 -0.136273</acceleration>
          <wrench>0 -0 0 0 -0 0</wrench>
        </link>
        <link name='crane_x7_gripper_finger_a_link'>
          <pose>-0.011711 -2.9e-05 1.66807 -9e-06 -0.010267 0.003017</pose>
          <velocity>0 0 0 -0 -2.1e-05 -1e-06</velocity>
          <acceleration>0 -0 0 -2.00325 0.73576 2.205</acceleration>
          <wrench>0 -0 0 0 -0 0</wrench>
        </link>
        <link name='crane_x7_gripper_finger_b_link'>
          <pose>0.012289 4.3e-05 1.66792 -9e-06 0.022505 0.003017</pose>
          <velocity>0 -0 -0 -0 2.2e-05 -1e-06</velocity>
          <acceleration>0 0 -0 0 -0 0</acceleration>
          <wrench>0 0 -0 0 -0 0</wrench>
        </link>
        <link name='crane_x7_lower_arm_fixed_part_link'>
          <pose>-0.000462 3e-06 1.375 -1.1e-05 0.001949 -7.5e-05</pose>
          <velocity>0 0 0 0 -0 0</velocity>
          <acceleration>0 0 0 -2.60628 -0.013072 0.050711</acceleration>
          <wrench>0 0 0 0 -0 0</wrench>
        </link>
        <link name='crane_x7_lower_arm_revolute_part_link'>
          <pose>-0.000226 4e-06 1.496 -3e-06 0.001949 0.003925</pose>
          <velocity>0 0 0 0 -0 0</velocity>
          <acceleration>0 -0 0 2.66473 0.02794 -0.028095</acceleration>
          <wrench>0 -0 0 0 -0 0</wrench>
        </link>
        <link name='crane_x7_shoulder_revolute_part_link'>
          <pose>0 0 1.061 0 0 -0.004</pose>
          <velocity>0 0 0 -0 -0 -0</velocity>
          <acceleration>-0 0 0 0.064459 -0.046467 0.01953</acceleration>
          <wrench>-0 0 0 0 -0 0</wrench>
        </link>
        <link name='crane_x7_upper_arm_fixed_part_link'>
          <pose>0 0 1.125 -2e-06 -0.001846 -0.004</pose>
          <velocity>0 0 0 0 -0 0</velocity>
          <acceleration>0 0 0 1.04643 -0.011189 0.001475</acceleration>
          <wrench>0 0 0 0 -0 0</wrench>
        </link>
        <link name='crane_x7_upper_arm_revolute_part_link'>
          <pose>-0.00012 1e-06 1.19 -1.1e-05 -0.001847 -7.5e-05</pose>
          <velocity>0 0 0 0 -0 0</velocity>
          <acceleration>0 0 0 -2.05489 0.010035 0.122253</acceleration>
          <wrench>0 0 0 0 -0 0</wrench>
        </link>
        <link name='crane_x7_wrist_link'>
          <pose>2.6e-05 6e-06 1.625 -3e-06 0.00612 0.003925</pose>
          <velocity>0 0 0 0 -0 0</velocity>
          <acceleration>0 -0 0 2.40541 -0.007019 2.25846</acceleration>
          <wrench>0 -0 0 0 -0 0</wrench>
        </link>
      </model>
      <model name='ground_plane'>
        <pose>0 0 0 0 -0 0</pose>
        <scale>1 1 1</scale>
        <link name='ground_plane::link'>
          <pose>0 0 0 0 -0 0</pose>
          <velocity>0 0 0 0 -0 0</velocity>
          <acceleration>0 0 0 0 -0 0</acceleration>
          <wrench>0 0 0 0 -0 0</wrench>
        </link>
      </model>
      <model name='kinect'>
        <pose>-0.018102 0.290835 1.45879 0.048524 0.616164 -0.461771</pose>
        <scale>1 1 1</scale>
        <link name='link'>
          <pose>-0.018102 0.290835 1.45879 0.048524 0.616164 -0.461771</pose>
          <velocity>0 0 0 0 -0 0</velocity>
          <acceleration>0 0 0 0 -0 0</acceleration>
          <wrench>0 0 0 0 -0 0</wrench>
        </link>
      </model>
      <model name='kinect_0'>
        <pose>1.96331 0.971141 1.6838 1e-06 0.176549 -2.40042</pose>
        <scale>1 1 1</scale>
        <link name='link'>
          <pose>1.96331 0.971141 1.6838 1e-06 0.176549 -2.40042</pose>
          <velocity>0 0 0 0 -0 0</velocity>
          <acceleration>0 0 0 0 -0 0</acceleration>
          <wrench>0 0 0 0 -0 0</wrench>
        </link>
      </model>
      <model name='kinect_1'>
        <pose>0.063623 -0.504239 1.36746 -0.095465 0.428044 0.742914</pose>
        <scale>1 1 1</scale>
        <link name='link'>
          <pose>0.063623 -0.504239 1.36746 -0.095465 0.428044 0.742914</pose>
          <velocity>0 0 0 0 -0 0</velocity>
          <acceleration>0 0 0 0 -0 0</acceleration>
          <wrench>0 0 0 0 -0 0</wrench>
        </link>
      </model>
      <model name='marker000'>
        <pose>0.7 0.15 1.014 0 -0 0</pose>
        <scale>1 1 1</scale>
        <link name='link'>
          <pose>0.7 0.15 1.014 0 -0 0</pose>
          <velocity>0 0 0 0 -0 0</velocity>
          <acceleration>0 0 0 0 -0 0</acceleration>
          <wrench>0 0 0 0 -0 0</wrench>
        </link>
      </model>
      <model name='marker001'>
        <pose>0.7 -0.15 1.014 0 -0 0</pose>
        <scale>1 1 1</scale>
        <link name='link'>
          <pose>0.7 -0.15 1.014 0 -0 0</pose>
          <velocity>0 0 0 0 -0 0</velocity>
          <acceleration>0 0 0 0 -0 0</acceleration>
          <wrench>0 0 0 0 -0 0</wrench>
        </link>
      </model>
      <model name='marker002'>
        <pose>0.4 0.15 1.014 0 -0 0</pose>
        <scale>1 1 1</scale>
        <link name='link'>
          <pose>0.4 0.15 1.014 0 -0 0</pose>
          <velocity>0 0 0 0 -0 0</velocity>
          <acceleration>0 0 0 0 -0 0</acceleration>
          <wrench>0 0 0 0 -0 0</wrench>
        </link>
      </model>
      <model name='marker003'>
        <pose>0.4 -0.15 1.014 0 -0 0</pose>
        <scale>1 1 1</scale>
        <link name='link'>
          <pose>0.4 -0.15 1.014 0 -0 0</pose>
          <velocity>0 0 0 0 -0 0</velocity>
          <acceleration>0 0 0 0 -0 0</acceleration>
          <wrench>0 0 0 0 -0 0</wrench>
        </link>
      </model>
      <model name='table'>
        <pose>0.438973 0.013251 0 0 -0 0.006788</pose>
        <scale>1 1 1</scale>
        <link name='table::link'>
          <pose>0.438973 0.013251 -0 0 -0 0.006788</pose>
          <velocity>0 0 0 0 -0 0</velocity>
          <acceleration>0 0 0 0 -0 0</acceleration>
          <wrench>0 0 0 0 -0 0</wrench>
        </link>
      </model>
      <model name='unit_sphere'>
        <pose>0.860372 0.133938 1.05093 0 -0 0</pose>
        <scale>0.071865 0.071865 0.071865</scale>
        <link name='link'>
          <pose>0.860372 0.133938 1.05093 0 -0 0</pose>
          <velocity>0 0 0 0 -0 0</velocity>
          <acceleration>0 0 0 0 -0 0</acceleration>
          <wrench>0 0 0 0 -0 0</wrench>
        </link>
      </model>
      <light name='sun'>
        <pose>0 0 10 0 -0 0</pose>
      </light>
    </state>
    <gui fullscreen='0'>
      <camera name='user_camera'>
        <pose>2.7629 -0.024053 1.53833 0 0.351645 -3.087</pose>
        <view_controller>orbit</view_controller>
        <projection_type>perspective</projection_type>
      </camera>
    </gui>
    <model name='kinect'>
      <pose>-0.357843 0.820598 0.036 0 -0 0</pose>
      <static>1</static>
      <link name='link'>
        <inertial>
          <mass>0.1</mass>
          <pose>0 0 0 0 -0 0</pose>
          <inertia>
            <ixx>1</ixx>
            <ixy>0</ixy>
            <ixz>0</ixz>
            <iyy>1</iyy>
            <iyz>0</iyz>
            <izz>1</izz>
          </inertia>
        </inertial>
        <collision name='collision'>
          <geometry>
            <box>
              <size>0.073 0.276 0.072</size>
            </box>
          </geometry>
          <max_contacts>10</max_contacts>
          <surface>
            <contact>
              <ode/>
            </contact>
            <bounce/>
            <friction>
              <torsional>
                <ode/>
              </torsional>
              <ode/>
            </friction>
          </surface>
        </collision>
        <visual name='visual'>
          <geometry>
            <mesh>
              <uri>model://kinect/meshes/kinect.dae</uri>
            </mesh>
          </geometry>
        </visual>
        <sensor name='camera' type='depth'>
          <update_rate>20</update_rate>
          <camera>
            <horizontal_fov>1.0472</horizontal_fov>
            <image>
              <width>640</width>
              <height>480</height>
              <format>R8G8B8</format>
            </image>
            <clip>
              <near>0.05</near>
              <far>3</far>
            </clip>
          </camera>
          <plugin name='camera_plugin' filename='libgazebo_ros_openni_kinect.so'>
            <baseline>0.2</baseline>
            <alwaysOn>1</alwaysOn>
            <updateRate>0.0</updateRate>
            <cameraName>camera_ir</cameraName>
            <imageTopicName>/camera0/color/image_raw</imageTopicName>
            <cameraInfoTopicName>/camera0/color/camera_info</cameraInfoTopicName>
            <depthImageTopicName>/camera0/depth/image_raw</depthImageTopicName>
            <depthImageCameraInfoTopicName>/camera0/depth/camera_info</depthImageCameraInfoTopicName>
            <pointCloudTopicName>/camera0/depth/points</pointCloudTopicName>
            <frameName>camera_link</frameName>
            <pointCloudCutoff>0.5</pointCloudCutoff>
            <pointCloudCutoffMax>3.0</pointCloudCutoffMax>
            <distortionK1>0</distortionK1>
            <distortionK2>0</distortionK2>
            <distortionK3>0</distortionK3>
            <distortionT1>0</distortionT1>
            <distortionT2>0</distortionT2>
            <CxPrime>0</CxPrime>
            <Cx>0</Cx>
            <Cy>0</Cy>
            <focalLength>0</focalLength>
            <hackBaseline>0</hackBaseline>
          </plugin>
        </sensor>
        <self_collide>0</self_collide>
        <enable_wind>0</enable_wind>
        <kinematic>0</kinematic>
      </link>
    </model>
    <model name='marker000'>
      <link name='link'>
        <self_collide>0</self_collide>
        <inertial>
          <pose>0 0 0 0 -0 0</pose>
          <inertia>
            <ixx>1</ixx>
            <ixy>0</ixy>
            <ixz>0</ixz>
            <iyy>1</iyy>
            <iyz>0</iyz>
            <izz>1</izz>
          </inertia>
          <mass>1</mass>
        </inertial>
        <enable_wind>0</enable_wind>
        <kinematic>0</kinematic>
        <pose>0 0 0 0 -0 0</pose>
        <visual name='visual'>
          <geometry>
            <box>
              <size>0.11 0.11 0.004</size>
            </box>
          </geometry>
          <material>
            <script>
              <uri>model://marker000/materials/marker000.material</uri>
              <name>marker000</name>
            </script>
            <shader type='pixel'/>
          </material>
          <pose>0 0 0 0 -0 0</pose>
          <transparency>0</transparency>
          <cast_shadows>1</cast_shadows>
        </visual>
      </link>
      <static>1</static>
      <allow_auto_disable>1</allow_auto_disable>
      <pose>-0.56716 1.31283 -34550.1 0 -0 0</pose>
    </model>
    <model name='marker001'>
      <link name='link'>
        <self_collide>0</self_collide>
        <inertial>
          <pose>0 0 0 0 -0 0</pose>
          <inertia>
            <ixx>1</ixx>
            <ixy>0</ixy>
            <ixz>0</ixz>
            <iyy>1</iyy>
            <iyz>0</iyz>
            <izz>1</izz>
          </inertia>
          <mass>1</mass>
        </inertial>
        <enable_wind>0</enable_wind>
        <kinematic>0</kinematic>
        <pose>0 0 0 0 -0 0</pose>
        <visual name='visual'>
          <geometry>
            <box>
              <size>0.11 0.11 0.004</size>
            </box>
          </geometry>
          <material>
            <script>
              <uri>model://marker001/materials/marker001.material</uri>
              <name>marker001</name>
            </script>
            <shader type='pixel'/>
          </material>
          <pose>0 0 0 0 -0 0</pose>
          <transparency>0</transparency>
          <cast_shadows>1</cast_shadows>
        </visual>
      </link>
      <static>1</static>
      <allow_auto_disable>1</allow_auto_disable>
      <pose>-0.190417 2.25225 -30450.6 0 -0 0</pose>
    </model>
    <model name='marker002'>
      <link name='link'>
        <self_collide>0</self_collide>
        <inertial>
          <pose>0 0 0 0 -0 0</pose>
          <inertia>
            <ixx>1</ixx>
            <ixy>0</ixy>
            <ixz>0</ixz>
            <iyy>1</iyy>
            <iyz>0</iyz>
            <izz>1</izz>
          </inertia>
          <mass>1</mass>
        </inertial>
        <enable_wind>0</enable_wind>
        <kinematic>0</kinematic>
        <pose>0 0 0 0 -0 0</pose>
        <visual name='visual'>
          <geometry>
            <box>
              <size>0.11 0.11 0.004</size>
            </box>
          </geometry>
          <material>
            <script>
              <uri>model://marker002/materials/marker002.material</uri>
              <name>marker002</name>
            </script>
            <shader type='pixel'/>
          </material>
          <pose>0 0 0 0 -0 0</pose>
          <transparency>0</transparency>
          <cast_shadows>1</cast_shadows>
        </visual>
      </link>
      <static>1</static>
      <allow_auto_disable>1</allow_auto_disable>
      <pose>-0.374532 3.31354 -27285.7 0 -0 0</pose>
    </model>
    <model name='marker003'>
      <link name='link'>
        <self_collide>0</self_collide>
        <inertial>
          <pose>0 0 0 0 -0 0</pose>
          <inertia>
            <ixx>1</ixx>
            <ixy>0</ixy>
            <ixz>0</ixz>
            <iyy>1</iyy>
            <iyz>0</iyz>
            <izz>1</izz>
          </inertia>
          <mass>1</mass>
        </inertial>
        <enable_wind>0</enable_wind>
        <kinematic>0</kinematic>
        <pose>0 0 0 0 -0 0</pose>
        <visual name='visual'>
          <geometry>
            <box>
              <size>0.11 0.11 0.004</size>
            </box>
          </geometry>
          <material>
            <script>
              <uri>model://marker003/materials/marker003.material</uri>
              <name>marker003</name>
            </script>
            <shader type='pixel'/>
          </material>
          <pose>0 0 0 0 -0 0</pose>
          <transparency>0</transparency>
          <cast_shadows>1</cast_shadows>
        </visual>
      </link>
      <static>1</static>
      <allow_auto_disable>1</allow_auto_disable>
      <pose>-0.41686 1.43447 0 0 -0 0</pose>
    </model>
    <model name='crane_x7'>
      <joint name='base_link_to_world_joint' type='fixed'>
        <pose relative_to='__model__'>0 0 0 0 -0 0</pose>
        <parent>world</parent>
        <child>base_link</child>
      </joint>
      <link name='base_link'>
        <pose relative_to='base_link_to_world_joint'>0 0 0 0 -0 0</pose>
        <inertial>
          <pose>-0.00673 -1e-06 0.0229 0 -0 0</pose>
          <mass>0.388</mass>
          <inertia>
            <ixx>0.000325</ixx>
            <ixy>1.2e-09</ixy>
            <ixz>-4.71e-05</ixz>
            <iyy>0.000483</iyy>
            <iyz>1.95e-08</iyz>
            <izz>0.000586</izz>
          </inertia>
        </inertial>
        <collision name='base_link_fixed_joint_lump__crane_x7_mounting_plate_link_collision'>
          <pose>0 0 0 0 -0 0</pose>
          <geometry>
            <mesh>
              <scale>1 1 1</scale>
              <uri>/home/ryo/catkin_ws/src/crane_x7_ros/crane_x7_description/meshes/collision/mounting_plate.stl</uri>
            </mesh>
          </geometry>
          <surface>
            <contact>
              <ode/>
            </contact>
            <friction>
              <ode/>
              <torsional>
                <ode/>
              </torsional>
            </friction>
            <bounce/>
          </surface>
          <max_contacts>10</max_contacts>
        </collision>
        <collision name='base_link_fixed_joint_lump__crane_x7_shoulder_fixed_part_link_collision_1'>
          <pose>0 0 0.005 0 -0 0</pose>
          <geometry>
            <mesh>
              <scale>1 1 1</scale>
              <uri>/home/ryo/catkin_ws/src/crane_x7_ros/crane_x7_description/meshes/collision/base_fixed_part.stl</uri>
            </mesh>
          </geometry>
          <surface>
            <contact>
              <ode/>
            </contact>
            <friction>
              <ode/>
              <torsional>
                <ode/>
              </torsional>
            </friction>
            <bounce/>
          </surface>
          <max_contacts>10</max_contacts>
        </collision>
        <visual name='base_link_fixed_joint_lump__crane_x7_mounting_plate_link_visual'>
          <pose>0 0 0 0 -0 0</pose>
          <geometry>
            <mesh>
              <scale>1 1 1</scale>
              <uri>/home/ryo/catkin_ws/src/crane_x7_ros/crane_x7_description/meshes/visual/mounting_plate.stl</uri>
            </mesh>
          </geometry>
          <material>
            <script>
              <name>Gazebo/Black</name>
              <uri>file://media/materials/scripts/gazebo.material</uri>
            </script>
          </material>
        </visual>
        <visual name='base_link_fixed_joint_lump__crane_x7_shoulder_fixed_part_link_visual_1'>
          <pose>0 0 0.005 0 -0 0</pose>
          <geometry>
            <mesh>
              <scale>1 1 1</scale>
              <uri>/home/ryo/catkin_ws/src/crane_x7_ros/crane_x7_description/meshes/visual/base_fixed_part.stl</uri>
            </mesh>
          </geometry>
          <material>
            <script>
              <name>Gazebo/Red</name>
              <uri>file://media/materials/scripts/gazebo.material</uri>
            </script>
          </material>
        </visual>
        <velocity_decay/>
        <gravity>1</gravity>
        <velocity_decay/>
        <self_collide>0</self_collide>
        <enable_wind>0</enable_wind>
        <kinematic>0</kinematic>
      </link>
      <joint name='crane_x7_shoulder_fixed_part_pan_joint' type='revolute'>
        <pose relative_to='base_link'>0 0 0.041 0 -0 0</pose>
        <parent>base_link</parent>
        <child>crane_x7_shoulder_revolute_part_link</child>
        <axis>
          <xyz>0 0 1</xyz>
          <limit>
            <lower>-2.97132</lower>
            <upper>2.97132</upper>
            <effort>10</effort>
            <velocity>4.81711</velocity>
          </limit>
          <dynamics>
            <damping>1e-06</damping>
            <friction>0.2</friction>
            <spring_reference>0</spring_reference>
            <spring_stiffness>0</spring_stiffness>
          </dynamics>
        </axis>
      </joint>
      <link name='crane_x7_shoulder_revolute_part_link'>
        <pose relative_to='crane_x7_shoulder_fixed_part_pan_joint'>0 0 0 0 -0 0</pose>
        <inertial>
          <pose>0.000243 -0.000105 0.047 0 -0 0</pose>
          <mass>0.253</mass>
          <inertia>
            <ixx>0.000179</ixx>
            <ixy>-7.32e-08</ixy>
            <ixz>8.89e-07</ixz>
            <iyy>0.000176</iyy>
            <iyz>6.23e-07</iyz>
            <izz>8.96e-05</izz>
          </inertia>
        </inertial>
        <collision name='crane_x7_shoulder_revolute_part_link_collision'>
          <pose>0 0 0.0296 0 -0 0</pose>
          <geometry>
            <cylinder>
              <length>0.0295</length>
              <radius>0.0334</radius>
            </cylinder>
          </geometry>
          <surface>
            <contact>
              <ode/>
            </contact>
            <friction>
              <ode/>
              <torsional>
                <ode/>
              </torsional>
            </friction>
            <bounce/>
          </surface>
          <max_contacts>10</max_contacts>
        </collision>
        <collision name='crane_x7_shoulder_revolute_part_link_collision_1'>
          <pose>0 0 0.064 1.57079 -0 0</pose>
          <geometry>
            <cylinder>
              <length>0.0491</length>
              <radius>0.034</radius>
            </cylinder>
          </geometry>
          <surface>
            <contact>
              <ode/>
            </contact>
            <friction>
              <ode/>
              <torsional>
                <ode/>
              </torsional>
            </friction>
            <bounce/>
          </surface>
          <max_contacts>10</max_contacts>
        </collision>
        <visual name='crane_x7_shoulder_revolute_part_link_visual'>
          <pose>0 0 0 0 -0 3.14159</pose>
          <geometry>
            <mesh>
              <scale>1 1 1</scale>
              <uri>/home/ryo/catkin_ws/src/crane_x7_ros/crane_x7_description/meshes/visual/base_revolute_part.stl</uri>
            </mesh>
          </geometry>
          <material>
            <script>
              <name>Gazebo/White</name>
              <uri>file://media/materials/scripts/gazebo.material</uri>
            </script>
          </material>
        </visual>
        <gravity>1</gravity>
        <velocity_decay/>
        <self_collide>0</self_collide>
        <enable_wind>0</enable_wind>
        <kinematic>0</kinematic>
      </link>
      <joint name='crane_x7_shoulder_revolute_part_tilt_joint' type='revolute'>
        <pose relative_to='crane_x7_shoulder_revolute_part_link'>0 0 0.064 0 -0 0</pose>
        <parent>crane_x7_shoulder_revolute_part_link</parent>
        <child>crane_x7_upper_arm_fixed_part_link</child>
        <axis>
          <xyz>0 -1 0</xyz>
          <limit>
            <lower>-1.57079</lower>
            <upper>1.57079</upper>
            <effort>10</effort>
            <velocity>4.81711</velocity>
          </limit>
          <dynamics>
            <damping>1e-06</damping>
            <friction>0.2</friction>
            <spring_reference>0</spring_reference>
            <spring_stiffness>0</spring_stiffness>
          </dynamics>
        </axis>
      </joint>
      <link name='crane_x7_upper_arm_fixed_part_link'>
        <pose relative_to='crane_x7_shoulder_revolute_part_tilt_joint'>0 0 0 0 -0 0</pose>
        <inertial>
          <pose>3.1e-05 1.9e-05 0.0342 1.57079 -0 0</pose>
          <mass>0.136</mass>
          <inertia>
            <ixx>0.000168</ixx>
            <ixy>2.05e-08</ixy>
            <ixz>-4e-07</ixz>
            <iyy>9.62e-05</iyy>
            <iyz>6.24e-08</iyz>
            <izz>0.000134</izz>
          </inertia>
        </inertial>
        <collision name='crane_x7_upper_arm_fixed_part_link_collision'>
          <pose>0 0 0 1.57079 -0 0</pose>
          <geometry>
            <mesh>
              <scale>1 1 1</scale>
              <uri>/home/ryo/catkin_ws/src/crane_x7_ros/crane_x7_description/meshes/collision/rotating_link_type_1_fixed_part.stl</uri>
            </mesh>
          </geometry>
          <surface>
            <contact>
              <ode/>
            </contact>
            <friction>
              <ode/>
              <torsional>
                <ode/>
              </torsional>
            </friction>
            <bounce/>
          </surface>
          <max_contacts>10</max_contacts>
        </collision>
        <collision name='crane_x7_upper_arm_fixed_part_link_fixed_joint_lump__crane_x7_upper_arm_fixed_part_joint_cover_l_link_collision_1'>
          <pose>0 0.0316 0 -1.57079 0 0</pose>
          <geometry>
            <mesh>
              <scale>1 1 1</scale>
              <uri>/home/ryo/catkin_ws/src/crane_x7_ros/crane_x7_description/meshes/visual/joint_cover.stl</uri>
            </mesh>
          </geometry>
          <surface>
            <contact>
              <ode/>
            </contact>
            <friction>
              <ode/>
              <torsional>
                <ode/>
              </torsional>
            </friction>
            <bounce/>
          </surface>
          <max_contacts>10</max_contacts>
        </collision>
        <collision name='crane_x7_upper_arm_fixed_part_link_fixed_joint_lump__crane_x7_upper_arm_fixed_part_joint_cover_r_link_collision_2'>
          <pose>0 -0.0316 0 1.57079 -0 0</pose>
          <geometry>
            <mesh>
              <scale>1 1 1</scale>
              <uri>/home/ryo/catkin_ws/src/crane_x7_ros/crane_x7_description/meshes/visual/joint_cover.stl</uri>
            </mesh>
          </geometry>
          <surface>
            <contact>
              <ode/>
            </contact>
            <friction>
              <ode/>
              <torsional>
                <ode/>
              </torsional>
            </friction>
            <bounce/>
          </surface>
          <max_contacts>10</max_contacts>
        </collision>
        <visual name='crane_x7_upper_arm_fixed_part_link_visual'>
          <pose>0 0 0 1.57079 -0 0</pose>
          <geometry>
            <mesh>
              <scale>1 1 1</scale>
              <uri>/home/ryo/catkin_ws/src/crane_x7_ros/crane_x7_description/meshes/visual/rotating_link_type_1_fixed_part.stl</uri>
            </mesh>
          </geometry>
          <material>
            <script>
              <name>Gazebo/White</name>
              <uri>file://media/materials/scripts/gazebo.material</uri>
            </script>
          </material>
        </visual>
        <visual name='crane_x7_upper_arm_fixed_part_link_fixed_joint_lump__crane_x7_upper_arm_fixed_part_joint_cover_l_link_visual_1'>
          <pose>0 0.0316 0 -1.57079 0 0</pose>
          <geometry>
            <mesh>
              <scale>1 1 1</scale>
              <uri>/home/ryo/catkin_ws/src/crane_x7_ros/crane_x7_description/meshes/visual/joint_cover.stl</uri>
            </mesh>
          </geometry>
          <material>
            <script>
              <name>Gazebo/Red</name>
              <uri>file://media/materials/scripts/gazebo.material</uri>
            </script>
          </material>
        </visual>
        <visual name='crane_x7_upper_arm_fixed_part_link_fixed_joint_lump__crane_x7_upper_arm_fixed_part_joint_cover_r_link_visual_2'>
          <pose>0 -0.0316 0 1.57079 -0 0</pose>
          <geometry>
            <mesh>
              <scale>1 1 1</scale>
              <uri>/home/ryo/catkin_ws/src/crane_x7_ros/crane_x7_description/meshes/visual/joint_cover.stl</uri>
            </mesh>
          </geometry>
          <material>
            <script>
              <name>Gazebo/Red</name>
              <uri>file://media/materials/scripts/gazebo.material</uri>
            </script>
          </material>
        </visual>
        <velocity_decay/>
        <velocity_decay/>
        <gravity>1</gravity>
        <velocity_decay/>
        <self_collide>0</self_collide>
        <enable_wind>0</enable_wind>
        <kinematic>0</kinematic>
      </link>
      <joint name='crane_x7_upper_arm_revolute_part_twist_joint' type='revolute'>
        <pose relative_to='crane_x7_upper_arm_fixed_part_link'>0 0 0.065 0 -0 0</pose>
        <parent>crane_x7_upper_arm_fixed_part_link</parent>
        <child>crane_x7_upper_arm_revolute_part_link</child>
        <axis>
          <xyz>0 0 1</xyz>
          <limit>
            <lower>-1.57079</lower>
            <upper>1.57079</upper>
            <effort>4</effort>
            <velocity>4.81711</velocity>
          </limit>
          <dynamics>
            <damping>1e-06</damping>
            <friction>0.2</friction>
            <spring_reference>0</spring_reference>
            <spring_stiffness>0</spring_stiffness>
          </dynamics>
        </axis>
      </joint>
      <link name='crane_x7_upper_arm_revolute_part_link'>
        <pose relative_to='crane_x7_upper_arm_revolute_part_twist_joint'>0 0 0 0 -0 0</pose>
        <inertial>
          <pose>-0.0137 -8.1e-05 0.0952 0 -0 0</pose>
          <mass>0.321</mass>
          <inertia>
            <ixx>0.00182</ixx>
            <ixy>7.54e-07</ixy>
            <ixz>-3.73e-05</ixz>
            <iyy>0.00188</iyy>
            <iyz>4.15e-06</iyz>
            <izz>0.000159</izz>
          </inertia>
        </inertial>
        <collision name='crane_x7_upper_arm_revolute_part_link_collision'>
          <pose>0 0 0 0 -0 0</pose>
          <geometry>
            <mesh>
              <scale>1 1 1</scale>
              <uri>/home/ryo/catkin_ws/src/crane_x7_ros/crane_x7_description/meshes/collision/rotating_link_type_1_revolute_part.stl</uri>
            </mesh>
          </geometry>
          <surface>
            <contact>
              <ode/>
            </contact>
            <friction>
              <ode/>
              <torsional>
                <ode/>
              </torsional>
            </friction>
            <bounce/>
          </surface>
          <max_contacts>10</max_contacts>
        </collision>
        <visual name='crane_x7_upper_arm_revolute_part_link_visual'>
          <pose>0 0 0 0 -0 0</pose>
          <geometry>
            <mesh>
              <scale>1 1 1</scale>
              <uri>/home/ryo/catkin_ws/src/crane_x7_ros/crane_x7_description/meshes/visual/rotating_link_type_1_revolute_part.stl</uri>
            </mesh>
          </geometry>
          <material>
            <script>
              <name>Gazebo/White</name>
              <uri>file://media/materials/scripts/gazebo.material</uri>
            </script>
          </material>
        </visual>
        <gravity>1</gravity>
        <velocity_decay/>
        <self_collide>0</self_collide>
        <enable_wind>0</enable_wind>
        <kinematic>0</kinematic>
      </link>
      <joint name='crane_x7_upper_arm_revolute_part_rotate_joint' type='revolute'>
        <pose relative_to='crane_x7_upper_arm_revolute_part_link'>0 0 0.185 0 -0 0</pose>
        <parent>crane_x7_upper_arm_revolute_part_link</parent>
        <child>crane_x7_lower_arm_fixed_part_link</child>
        <axis>
          <xyz>0 -1 0</xyz>
          <limit>
            <lower>-2.80718</lower>
            <upper>0.04141</upper>
            <effort>4</effort>
            <velocity>4.81711</velocity>
          </limit>
          <dynamics>
            <damping>1e-06</damping>
            <friction>0.2</friction>
            <spring_reference>0</spring_reference>
            <spring_stiffness>0</spring_stiffness>
          </dynamics>
        </axis>
      </joint>
      <link name='crane_x7_lower_arm_fixed_part_link'>
        <pose relative_to='crane_x7_upper_arm_revolute_part_rotate_joint'>0 0 0 0 -0 0</pose>
        <inertial>
          <pose>-0.00939 6.4e-05 0.0804 1.57079 -0 0</pose>
          <mass>0.222</mass>
          <inertia>
            <ixx>0.000489</ixx>
            <ixy>-3.9e-06</ixy>
            <ixz>8.29e-08</ixz>
            <iyy>0.000114</iyy>
            <iyz>2.82e-06</iyz>
            <izz>0.000503</izz>
          </inertia>
        </inertial>
        <collision name='crane_x7_lower_arm_fixed_part_link_collision'>
          <pose>0 0 0 1.57079 -0 0</pose>
          <geometry>
            <mesh>
              <scale>1 1 1</scale>
              <uri>/home/ryo/catkin_ws/src/crane_x7_ros/crane_x7_description/meshes/collision/rotating_link_type_2_fixed_part.stl</uri>
            </mesh>
          </geometry>
          <surface>
            <contact>
              <ode/>
            </contact>
            <friction>
              <ode/>
              <torsional>
                <ode/>
              </torsional>
            </friction>
            <bounce/>
          </surface>
          <max_contacts>10</max_contacts>
        </collision>
        <collision name='crane_x7_lower_arm_fixed_part_link_fixed_joint_lump__crane_x7_lower_arm_fixed_part_joint_cover_l_link_collision_1'>
          <pose>0 0.025 0 -1.57079 0 0</pose>
          <geometry>
            <mesh>
              <scale>1 1 1</scale>
              <uri>/home/ryo/catkin_ws/src/crane_x7_ros/crane_x7_description/meshes/visual/joint_cover.stl</uri>
            </mesh>
          </geometry>
          <surface>
            <contact>
              <ode/>
            </contact>
            <friction>
              <ode/>
              <torsional>
                <ode/>
              </torsional>
            </friction>
            <bounce/>
          </surface>
          <max_contacts>10</max_contacts>
        </collision>
        <collision name='crane_x7_lower_arm_fixed_part_link_fixed_joint_lump__crane_x7_lower_arm_fixed_part_joint_cover_r_link_collision_2'>
          <pose>0 -0.025 0 1.57079 -0 0</pose>
          <geometry>
            <mesh>
              <scale>1 1 1</scale>
              <uri>/home/ryo/catkin_ws/src/crane_x7_ros/crane_x7_description/meshes/visual/joint_cover.stl</uri>
            </mesh>
          </geometry>
          <surface>
            <contact>
              <ode/>
            </contact>
            <friction>
              <ode/>
              <torsional>
                <ode/>
              </torsional>
            </friction>
            <bounce/>
          </surface>
          <max_contacts>10</max_contacts>
        </collision>
        <visual name='crane_x7_lower_arm_fixed_part_link_visual'>
          <pose>0 0 0 1.57079 -0 0</pose>
          <geometry>
            <mesh>
              <scale>1 1 1</scale>
              <uri>/home/ryo/catkin_ws/src/crane_x7_ros/crane_x7_description/meshes/visual/rotating_link_type_2_fixed_part.stl</uri>
            </mesh>
          </geometry>
          <material>
            <script>
              <name>Gazebo/White</name>
              <uri>file://media/materials/scripts/gazebo.material</uri>
            </script>
          </material>
        </visual>
        <visual name='crane_x7_lower_arm_fixed_part_link_fixed_joint_lump__crane_x7_lower_arm_fixed_part_joint_cover_l_link_visual_1'>
          <pose>0 0.025 0 -1.57079 0 0</pose>
          <geometry>
            <mesh>
              <scale>1 1 1</scale>
              <uri>/home/ryo/catkin_ws/src/crane_x7_ros/crane_x7_description/meshes/visual/joint_cover.stl</uri>
            </mesh>
          </geometry>
          <material>
            <script>
              <name>Gazebo/Red</name>
              <uri>file://media/materials/scripts/gazebo.material</uri>
            </script>
          </material>
        </visual>
        <visual name='crane_x7_lower_arm_fixed_part_link_fixed_joint_lump__crane_x7_lower_arm_fixed_part_joint_cover_r_link_visual_2'>
          <pose>0 -0.025 0 1.57079 -0 0</pose>
          <geometry>
            <mesh>
              <scale>1 1 1</scale>
              <uri>/home/ryo/catkin_ws/src/crane_x7_ros/crane_x7_description/meshes/visual/joint_cover.stl</uri>
            </mesh>
          </geometry>
          <material>
            <script>
              <name>Gazebo/Red</name>
              <uri>file://media/materials/scripts/gazebo.material</uri>
            </script>
          </material>
        </visual>
        <velocity_decay/>
        <velocity_decay/>
        <gravity>1</gravity>
        <velocity_decay/>
        <self_collide>0</self_collide>
        <enable_wind>0</enable_wind>
        <kinematic>0</kinematic>
      </link>
      <joint name='crane_x7_lower_arm_fixed_part_joint' type='revolute'>
        <pose relative_to='crane_x7_lower_arm_fixed_part_link'>0 0 0.121 0 -0 0</pose>
        <parent>crane_x7_lower_arm_fixed_part_link</parent>
        <child>crane_x7_lower_arm_revolute_part_link</child>
        <axis>
          <xyz>0 0 1</xyz>
          <limit>
            <lower>-2.77343</lower>
            <upper>1.51403</upper>
            <effort>4</effort>
            <velocity>4.81711</velocity>
          </limit>
          <dynamics>
            <damping>1e-06</damping>
            <friction>0.2</friction>
            <spring_reference>0</spring_reference>
            <spring_stiffness>0</spring_stiffness>
          </dynamics>
        </axis>
      </joint>
      <link name='crane_x7_lower_arm_revolute_part_link'>
        <pose relative_to='crane_x7_lower_arm_fixed_part_joint'>0 0 0 0 -0 0</pose>
        <inertial>
          <pose>-8.4e-05 0.000462 0.0637 0 -0 0</pose>
          <mass>0.207</mass>
          <inertia>
            <ixx>0.00029</ixx>
            <ixy>1e-07</ixy>
            <ixz>-4.77e-07</ixz>
            <iyy>0.000257</iyy>
            <iyz>-1.69e-05</iyz>
            <izz>8.75e-05</izz>
          </inertia>
        </inertial>
        <collision name='crane_x7_lower_arm_revolute_part_link_collision'>
          <pose>0 0 0 0 -0 0</pose>
          <geometry>
            <mesh>
              <scale>1 1 1</scale>
              <uri>/home/ryo/catkin_ws/src/crane_x7_ros/crane_x7_description/meshes/collision/rotating_link_type_2_revolute_part.stl</uri>
            </mesh>
          </geometry>
          <surface>
            <contact>
              <ode/>
            </contact>
            <friction>
              <ode/>
              <torsional>
                <ode/>
              </torsional>
            </friction>
            <bounce/>
          </surface>
          <max_contacts>10</max_contacts>
        </collision>
        <collision name='crane_x7_lower_arm_revolute_part_link_fixed_joint_lump__crane_x7_lower_arm_revolute_part_logo_symbol_l_link_collision_1'>
          <pose>0 0.0345 0.132 1.57079 1.57079 3.14159</pose>
          <geometry>
            <mesh>
              <scale>1 1 1</scale>
              <uri>/home/ryo/catkin_ws/src/crane_x7_ros/crane_x7_description/meshes/visual/rtcorp_logo_rabbit.stl</uri>
            </mesh>
          </geometry>
          <surface>
            <contact>
              <ode/>
            </contact>
            <friction>
              <ode/>
              <torsional>
                <ode/>
              </torsional>
            </friction>
            <bounce/>
          </surface>
          <max_contacts>10</max_contacts>
        </collision>
        <collision name='crane_x7_lower_arm_revolute_part_link_fixed_joint_lump__crane_x7_lower_arm_revolute_part_logo_symbol_r_link_collision_2'>
          <pose>0 -0.0345 0.065 -1.57079 -1.57079 3.14159</pose>
          <geometry>
            <mesh>
              <scale>1 1 1</scale>
              <uri>/home/ryo/catkin_ws/src/crane_x7_ros/crane_x7_description/meshes/visual/rtcorp_logo_rabbit.stl</uri>
            </mesh>
          </geometry>
          <surface>
            <contact>
              <ode/>
            </contact>
            <friction>
              <ode/>
              <torsional>
                <ode/>
              </torsional>
            </friction>
            <bounce/>
          </surface>
          <max_contacts>10</max_contacts>
        </collision>
        <collision name='crane_x7_lower_arm_revolute_part_link_fixed_joint_lump__crane_x7_lower_arm_revolute_part_logo_text_l_link_collision_3'>
          <pose>0 0.0345 0.095 1.57079 1.57079 3.14159</pose>
          <geometry>
            <mesh>
              <scale>1 1 1</scale>
              <uri>/home/ryo/catkin_ws/src/crane_x7_ros/crane_x7_description/meshes/visual/rtcorp_logo_name.stl</uri>
            </mesh>
          </geometry>
          <surface>
            <contact>
              <ode/>
            </contact>
            <friction>
              <ode/>
              <torsional>
                <ode/>
              </torsional>
            </friction>
            <bounce/>
          </surface>
          <max_contacts>10</max_contacts>
        </collision>
        <collision name='crane_x7_lower_arm_revolute_part_link_fixed_joint_lump__crane_x7_lower_arm_revolute_part_logo_text_r_link_collision_4'>
          <pose>0 -0.0345 0.104 -1.57079 -1.57079 3.14159</pose>
          <geometry>
            <mesh>
              <scale>1 1 1</scale>
              <uri>/home/ryo/catkin_ws/src/crane_x7_ros/crane_x7_description/meshes/visual/rtcorp_logo_name.stl</uri>
            </mesh>
          </geometry>
          <surface>
            <contact>
              <ode/>
            </contact>
            <friction>
              <ode/>
              <torsional>
                <ode/>
              </torsional>
            </friction>
            <bounce/>
          </surface>
          <max_contacts>10</max_contacts>
        </collision>
        <visual name='crane_x7_lower_arm_revolute_part_link_visual'>
          <pose>0 0 0 0 -0 0</pose>
          <geometry>
            <mesh>
              <scale>1 1 1</scale>
              <uri>/home/ryo/catkin_ws/src/crane_x7_ros/crane_x7_description/meshes/visual/rotating_link_type_2_revolute_part.stl</uri>
            </mesh>
          </geometry>
          <material>
            <script>
              <name>Gazebo/White</name>
              <uri>file://media/materials/scripts/gazebo.material</uri>
            </script>
          </material>
        </visual>
        <visual name='crane_x7_lower_arm_revolute_part_link_fixed_joint_lump__crane_x7_lower_arm_revolute_part_logo_symbol_l_link_visual_1'>
          <pose>0 0.0345 0.132 1.57079 1.57079 3.14159</pose>
          <geometry>
            <mesh>
              <scale>1 1 1</scale>
              <uri>/home/ryo/catkin_ws/src/crane_x7_ros/crane_x7_description/meshes/visual/rtcorp_logo_rabbit.stl</uri>
            </mesh>
          </geometry>
          <material>
            <script>
              <name>Gazebo/Red</name>
              <uri>file://media/materials/scripts/gazebo.material</uri>
            </script>
          </material>
        </visual>
        <visual name='crane_x7_lower_arm_revolute_part_link_fixed_joint_lump__crane_x7_lower_arm_revolute_part_logo_symbol_r_link_visual_2'>
          <pose>0 -0.0345 0.065 -1.57079 -1.57079 3.14159</pose>
          <geometry>
            <mesh>
              <scale>1 1 1</scale>
              <uri>/home/ryo/catkin_ws/src/crane_x7_ros/crane_x7_description/meshes/visual/rtcorp_logo_rabbit.stl</uri>
            </mesh>
          </geometry>
          <material>
            <script>
              <name>Gazebo/Red</name>
              <uri>file://media/materials/scripts/gazebo.material</uri>
            </script>
          </material>
        </visual>
        <visual name='crane_x7_lower_arm_revolute_part_link_fixed_joint_lump__crane_x7_lower_arm_revolute_part_logo_text_l_link_visual_3'>
          <pose>0 0.0345 0.095 1.57079 1.57079 3.14159</pose>
          <geometry>
            <mesh>
              <scale>1 1 1</scale>
              <uri>/home/ryo/catkin_ws/src/crane_x7_ros/crane_x7_description/meshes/visual/rtcorp_logo_name.stl</uri>
            </mesh>
          </geometry>
          <material>
            <script>
              <name>Gazebo/Black</name>
              <uri>file://media/materials/scripts/gazebo.material</uri>
            </script>
          </material>
        </visual>
        <visual name='crane_x7_lower_arm_revolute_part_link_fixed_joint_lump__crane_x7_lower_arm_revolute_part_logo_text_r_link_visual_4'>
          <pose>0 -0.0345 0.104 -1.57079 -1.57079 3.14159</pose>
          <geometry>
            <mesh>
              <scale>1 1 1</scale>
              <uri>/home/ryo/catkin_ws/src/crane_x7_ros/crane_x7_description/meshes/visual/rtcorp_logo_name.stl</uri>
            </mesh>
          </geometry>
          <material>
            <script>
              <name>Gazebo/Black</name>
              <uri>file://media/materials/scripts/gazebo.material</uri>
            </script>
          </material>
        </visual>
        <velocity_decay/>
        <velocity_decay/>
        <velocity_decay/>
        <velocity_decay/>
        <gravity>1</gravity>
        <velocity_decay/>
        <self_collide>0</self_collide>
        <enable_wind>0</enable_wind>
        <kinematic>0</kinematic>
      </link>
      <joint name='crane_x7_lower_arm_revolute_part_joint' type='revolute'>
        <pose relative_to='crane_x7_lower_arm_revolute_part_link'>0 0 0.129 0 -0 0</pose>
        <parent>crane_x7_lower_arm_revolute_part_link</parent>
        <child>crane_x7_wrist_link</child>
        <axis>
          <xyz>0 -1 0</xyz>
          <limit>
            <lower>-1.57079</lower>
            <upper>1.57079</upper>
            <effort>4</effort>
            <velocity>4.81711</velocity>
          </limit>
          <dynamics>
            <damping>1e-06</damping>
            <friction>0.2</friction>
            <spring_reference>0</spring_reference>
            <spring_stiffness>0</spring_stiffness>
          </dynamics>
        </axis>
      </joint>
      <link name='crane_x7_wrist_link'>
        <pose relative_to='crane_x7_lower_arm_revolute_part_joint'>0 0 0 0 -0 0</pose>
        <inertial>
          <pose>0.0061 0.000826 -0.00355 1.57079 -0 0</pose>
          <mass>0.14</mass>
          <inertia>
            <ixx>4.01e-05</ixx>
            <ixy>-2.91e-06</ixy>
            <ixz>6.39e-07</ixz>
            <iyy>6.13e-05</iyy>
            <iyz>-4.9e-07</iyz>
            <izz>7.35e-05</izz>
          </inertia>
        </inertial>
        <collision name='crane_x7_wrist_link_collision'>
          <pose>0 0 0 1.57079 -0 0</pose>
          <geometry>
            <mesh>
              <scale>1 1 1</scale>
              <uri>/home/ryo/catkin_ws/src/crane_x7_ros/crane_x7_description/meshes/collision/wrist.stl</uri>
            </mesh>
          </geometry>
          <surface>
            <contact>
              <ode/>
            </contact>
            <friction>
              <ode/>
              <torsional>
                <ode/>
              </torsional>
            </friction>
            <bounce/>
          </surface>
          <max_contacts>10</max_contacts>
        </collision>
        <visual name='crane_x7_wrist_link_visual'>
          <pose>0 0 0 1.57079 -0 0</pose>
          <geometry>
            <mesh>
              <scale>1 1 1</scale>
              <uri>/home/ryo/catkin_ws/src/crane_x7_ros/crane_x7_description/meshes/visual/wrist.stl</uri>
            </mesh>
          </geometry>
          <material>
            <script>
              <name>Gazebo/White</name>
              <uri>file://media/materials/scripts/gazebo.material</uri>
            </script>
          </material>
        </visual>
        <gravity>1</gravity>
        <velocity_decay/>
        <self_collide>0</self_collide>
        <enable_wind>0</enable_wind>
        <kinematic>0</kinematic>
      </link>
      <joint name='crane_x7_wrist_joint' type='revolute'>
        <pose relative_to='crane_x7_wrist_link'>0 0 0.019 0 -0 0</pose>
        <parent>crane_x7_wrist_link</parent>
        <child>crane_x7_gripper_base_link</child>
        <axis>
          <xyz>0 0 1</xyz>
          <limit>
            <lower>-2.96365</lower>
            <upper>2.97132</upper>
            <effort>4</effort>
            <velocity>4.81711</velocity>
          </limit>
          <dynamics>
            <damping>1e-06</damping>
            <friction>0.2</friction>
            <spring_reference>0</spring_reference>
            <spring_stiffness>0</spring_stiffness>
          </dynamics>
        </axis>
      </joint>
      <link name='crane_x7_gripper_base_link'>
        <pose relative_to='crane_x7_wrist_joint'>0 0 0 0 -0 0</pose>
        <inertial>
          <pose>0.000108 -0.00103 0.0208 0 -0 0</pose>
          <mass>0.121</mass>
          <inertia>
            <ixx>3.2e-05</ixx>
            <ixy>-9.45e-08</ixy>
            <ixz>2.61e-07</ixz>
            <iyy>4.14e-05</iyy>
            <iyz>3.88e-07</iyz>
            <izz>4.29e-05</izz>
          </inertia>
        </inertial>
        <collision name='crane_x7_gripper_base_link_collision'>
          <pose>0 0 0 0 -0 0</pose>
          <geometry>
            <mesh>
              <scale>1 1 1</scale>
              <uri>/home/ryo/catkin_ws/src/crane_x7_ros/crane_x7_description/meshes/collision/wide_two_finger_gripper_actuator.stl</uri>
            </mesh>
          </geometry>
          <surface>
            <contact>
              <ode/>
            </contact>
            <friction>
              <ode/>
              <torsional>
                <ode/>
              </torsional>
            </friction>
            <bounce/>
          </surface>
          <max_contacts>10</max_contacts>
        </collision>
        <visual name='crane_x7_gripper_base_link_visual'>
          <pose>0 0 0 0 -0 0</pose>
          <geometry>
            <mesh>
              <scale>1 1 1</scale>
              <uri>/home/ryo/catkin_ws/src/crane_x7_ros/crane_x7_description/meshes/visual/wide_two_finger_gripper_actuator.stl</uri>
            </mesh>
          </geometry>
          <material>
            <script>
              <name>Gazebo/Red</name>
              <uri>file://media/materials/scripts/gazebo.material</uri>
            </script>
          </material>
        </visual>
        <gravity>1</gravity>
        <velocity_decay/>
        <self_collide>0</self_collide>
        <enable_wind>0</enable_wind>
        <kinematic>0</kinematic>
      </link>
      <joint name='crane_x7_gripper_finger_a_joint' type='revolute'>
        <pose relative_to='crane_x7_gripper_base_link'>-0.012 0 0.024 0 -0 0</pose>
        <parent>crane_x7_gripper_base_link</parent>
        <child>crane_x7_gripper_finger_a_link</child>
        <axis>
          <xyz>0 -1 0</xyz>
          <limit>
            <lower>0.0046</lower>
            <upper>1.62601</upper>
            <effort>4</effort>
            <velocity>4.81711</velocity>
          </limit>
          <dynamics>
            <damping>1e-06</damping>
            <friction>0.8</friction>
            <spring_reference>0</spring_reference>
            <spring_stiffness>0</spring_stiffness>
          </dynamics>
        </axis>
      </joint>
      <link name='crane_x7_gripper_finger_a_link'>
        <pose relative_to='crane_x7_gripper_finger_a_joint'>0 0 0 0 -0 0</pose>
        <inertial>
          <pose>-0.00265 0.00354 0.0269 1.57079 -0 0</pose>
          <mass>0.0158</mass>
          <inertia>
            <ixx>1.01e-05</ixx>
            <ixy>-1.97e-07</ixy>
            <ixz>-9.89e-08</ixz>
            <iyy>4.95e-06</iyy>
            <iyz>5.37e-07</iyz>
            <izz>6.24e-06</izz>
          </inertia>
        </inertial>
        <collision name='crane_x7_gripper_finger_a_link_collision'>
          <pose>0 0 0 1.57079 -0 0</pose>
          <geometry>
            <mesh>
              <scale>1 1 1</scale>
              <uri>/home/ryo/catkin_ws/src/crane_x7_ros/crane_x7_description/meshes/collision/wide_two_finger_gripper_finger_a.stl</uri>
            </mesh>
          </geometry>
          <surface>
            <contact>
              <ode/>
            </contact>
            <friction>
              <ode>
                <mu>0.8</mu>
                <mu2>0.8</mu2>
              </ode>
              <torsional>
                <ode/>
              </torsional>
            </friction>
            <bounce/>
          </surface>
          <max_contacts>10</max_contacts>
        </collision>
        <visual name='crane_x7_gripper_finger_a_link_visual'>
          <pose>0 0 0 1.57079 -0 0</pose>
          <geometry>
            <mesh>
              <scale>1 1 1</scale>
              <uri>/home/ryo/catkin_ws/src/crane_x7_ros/crane_x7_description/meshes/visual/wide_two_finger_gripper_finger_a.stl</uri>
            </mesh>
          </geometry>
          <material>
            <script>
              <name>Gazebo/Red</name>
              <uri>file://media/materials/scripts/gazebo.material</uri>
            </script>
          </material>
        </visual>
        <gravity>1</gravity>
        <velocity_decay/>
        <self_collide>0</self_collide>
        <enable_wind>0</enable_wind>
        <kinematic>0</kinematic>
      </link>
      <joint name='crane_x7_gripper_finger_b_joint' type='revolute'>
        <pose relative_to='crane_x7_gripper_base_link'>0.012 0 0.024 0 -0 0</pose>
        <parent>crane_x7_gripper_base_link</parent>
        <child>crane_x7_gripper_finger_b_link</child>
        <axis>
          <xyz>0 1 0</xyz>
          <limit>
            <lower>0.0046</lower>
            <upper>1.62601</upper>
            <effort>4</effort>
            <velocity>4.81711</velocity>
          </limit>
          <dynamics>
            <damping>1e-06</damping>
            <friction>0.8</friction>
            <spring_reference>0</spring_reference>
            <spring_stiffness>0</spring_stiffness>
          </dynamics>
        </axis>
      </joint>
      <link name='crane_x7_gripper_finger_b_link'>
        <pose relative_to='crane_x7_gripper_finger_b_joint'>0 0 0 0 -0 0</pose>
        <inertial>
          <pose>0.00301 0.00285 0.0309 1.57079 -0 0</pose>
          <mass>0.0139</mass>
          <inertia>
            <ixx>7.48e-06</ixx>
            <ixy>3.61e-07</ixy>
            <ixz>6.34e-08</ixz>
            <iyy>4.09e-06</iyy>
            <iyz>2.28e-07</iyz>
            <izz>4.37e-06</izz>
          </inertia>
        </inertial>
        <collision name='crane_x7_gripper_finger_b_link_collision'>
          <pose>0 0 0 1.57079 -0 0</pose>
          <geometry>
            <mesh>
              <scale>1 1 1</scale>
              <uri>/home/ryo/catkin_ws/src/crane_x7_ros/crane_x7_description/meshes/collision/wide_two_finger_gripper_finger_b.stl</uri>
            </mesh>
          </geometry>
          <surface>
            <contact>
              <ode/>
            </contact>
            <friction>
              <ode>
                <mu>0.8</mu>
                <mu2>0.8</mu2>
              </ode>
              <torsional>
                <ode/>
              </torsional>
            </friction>
            <bounce/>
          </surface>
          <max_contacts>10</max_contacts>
        </collision>
        <visual name='crane_x7_gripper_finger_b_link_visual'>
          <pose>0 0 0 1.57079 -0 0</pose>
          <geometry>
            <mesh>
              <scale>1 1 1</scale>
              <uri>/home/ryo/catkin_ws/src/crane_x7_ros/crane_x7_description/meshes/visual/wide_two_finger_gripper_finger_b.stl</uri>
            </mesh>
          </geometry>
          <material>
            <script>
              <name>Gazebo/Red</name>
              <uri>file://media/materials/scripts/gazebo.material</uri>
            </script>
          </material>
        </visual>
        <gravity>1</gravity>
        <velocity_decay/>
        <self_collide>0</self_collide>
        <enable_wind>0</enable_wind>
        <kinematic>0</kinematic>
      </link>
      <plugin name='gazebo_ros_control' filename='libgazebo_ros_control.so'>
        <robotNamespace>/crane_x7</robotNamespace>
        <robotSimType>gazebo_ros_control/DefaultRobotHWSim</robotSimType>
        <legacyModeNS>0</legacyModeNS>
      </plugin>
      <static>0</static>
      <plugin name='crane_x7_gripper_mimic_joint' filename='libroboticsgroup_gazebo_mimic_joint_plugin.so'>
        <joint>crane_x7_gripper_finger_a_joint</joint>
        <mimicJoint>crane_x7_gripper_finger_b_joint</mimicJoint>
        <multiplier>1</multiplier>
        <robotNamespace>/</robotNamespace>
      </plugin>
      <pose>0 0 1.02 0 -0 0</pose>
    </model>
    <model name='kinect_0'>
      <link name='link'>
        <inertial>
          <mass>0.1</mass>
          <pose>0 0 0 0 -0 0</pose>
          <inertia>
            <ixx>1</ixx>
            <ixy>0</ixy>
            <ixz>0</ixz>
            <iyy>1</iyy>
            <iyz>0</iyz>
            <izz>1</izz>
          </inertia>
        </inertial>
        <sensor name='camera' type='depth'>
          <update_rate>20</update_rate>
          <camera>
            <horizontal_fov>1.0472</horizontal_fov>
            <image>
              <width>640</width>
              <height>480</height>
              <format>R8G8B8</format>
            </image>
            <clip>
              <near>0.05</near>
              <far>3</far>
            </clip>
          </camera>
          <plugin name='camera_plugin' filename='libgazebo_ros_openni_kinect.so'>
            <baseline>0.2</baseline>
            <alwaysOn>1</alwaysOn>
            <updateRate>0.0</updateRate>
            <cameraName>camera_ir</cameraName>
            <imageTopicName>/camera1/color/image_raw</imageTopicName>
            <cameraInfoTopicName>/camera1/color/camera_info</cameraInfoTopicName>
            <depthImageTopicName>/camera1/depth/image_raw</depthImageTopicName>
            <depthImageCameraInfoTopicName>/camera1/depth/camera_info</depthImageCameraInfoTopicName>
            <pointCloudTopicName>/camera1/depth/points</pointCloudTopicName>
            <frameName>camera_link</frameName>
            <pointCloudCutoff>0.5</pointCloudCutoff>
            <pointCloudCutoffMax>3.0</pointCloudCutoffMax>
            <distortionK1>0</distortionK1>
            <distortionK2>0</distortionK2>
            <distortionK3>0</distortionK3>
            <distortionT1>0</distortionT1>
            <distortionT2>0</distortionT2>
            <CxPrime>0</CxPrime>
            <Cx>0</Cx>
            <Cy>0</Cy>
            <focalLength>0</focalLength>
            <hackBaseline>0</hackBaseline>
          </plugin>
        </sensor>
        <self_collide>0</self_collide>
        <enable_wind>0</enable_wind>
        <kinematic>0</kinematic>
        <pose>0 0 0 0 -0 0</pose>
        <visual name='visual'>
          <geometry>
            <mesh>
              <uri>model://kinect/meshes/kinect.dae</uri>
            </mesh>
          </geometry>
          <material>
            <shader type='pixel'/>
          </material>
          <pose>0 0 0 0 -0 0</pose>
          <transparency>0</transparency>
          <cast_shadows>1</cast_shadows>
        </visual>
        <collision name='collision'>
          <laser_retro>0</laser_retro>
          <max_contacts>10</max_contacts>
          <pose>0 0 0 0 -0 0</pose>
          <geometry>
            <box>
              <size>0.073 0.276 0.072</size>
            </box>
          </geometry>
          <surface>
            <friction>
              <ode>
                <mu>1</mu>
                <mu2>1</mu2>
                <fdir1>0 0 0</fdir1>
                <slip1>0</slip1>
                <slip2>0</slip2>
              </ode>
              <torsional>
                <coefficient>1</coefficient>
                <patch_radius>0</patch_radius>
                <surface_radius>0</surface_radius>
                <use_patch_radius>1</use_patch_radius>
                <ode>
                  <slip>0</slip>
                </ode>
              </torsional>
            </friction>
            <bounce>
              <restitution_coefficient>0</restitution_coefficient>
              <threshold>1e+06</threshold>
            </bounce>
            <contact>
              <collide_without_contact>0</collide_without_contact>
              <collide_without_contact_bitmask>1</collide_without_contact_bitmask>
              <collide_bitmask>1</collide_bitmask>
              <ode>
                <soft_cfm>0</soft_cfm>
                <soft_erp>0.2</soft_erp>
                <kp>1e+13</kp>
                <kd>1</kd>
                <max_vel>0.01</max_vel>
                <min_depth>0</min_depth>
              </ode>
              <bullet>
                <split_impulse>1</split_impulse>
                <split_impulse_penetration_threshold>-0.01</split_impulse_penetration_threshold>
                <soft_cfm>0</soft_cfm>
                <soft_erp>0.2</soft_erp>
                <kp>1e+13</kp>
                <kd>1</kd>
              </bullet>
            </contact>
          </surface>
        </collision>
      </link>
      <static>1</static>
      <allow_auto_disable>1</allow_auto_disable>
      <pose>1.53306 1.12399 0.036 -2e-06 0 1e-06</pose>
    </model>
    <model name='unit_sphere'>
      <pose>0.604759 1.22596 0.5 0 -0 0</pose>
      <link name='link'>
        <inertial>
          <mass>1</mass>
          <inertia>
            <ixx>0.1</ixx>
            <ixy>0</ixy>
            <ixz>0</ixz>
            <iyy>0.1</iyy>
            <iyz>0</iyz>
            <izz>0.1</izz>
          </inertia>
          <pose>0 0 0 0 -0 0</pose>
        </inertial>
        <collision name='collision'>
          <geometry>
            <sphere>
              <radius>0.5</radius>
            </sphere>
          </geometry>
          <max_contacts>10</max_contacts>
          <surface>
            <contact>
              <ode/>
            </contact>
            <bounce/>
            <friction>
              <torsional>
                <ode/>
              </torsional>
              <ode/>
            </friction>
          </surface>
        </collision>
        <visual name='visual'>
          <geometry>
            <sphere>
              <radius>0.5</radius>
            </sphere>
          </geometry>
          <material>
            <script>
              <name>Gazebo/Grey</name>
              <uri>file://media/materials/scripts/gazebo.material</uri>
            </script>
          </material>
        </visual>
        <self_collide>0</self_collide>
        <enable_wind>0</enable_wind>
        <kinematic>0</kinematic>
      </link>
    </model>
    <model name='kinect_1'>
      <link name='link'>
        <inertial>
          <mass>0.1</mass>
          <pose>0 0 0 0 -0 0</pose>
          <inertia>
            <ixx>1</ixx>
            <ixy>0</ixy>
            <ixz>0</ixz>
            <iyy>1</iyy>
            <iyz>0</iyz>
            <izz>1</izz>
          </inertia>
        </inertial>
        <sensor name='camera' type='depth'>
          <update_rate>20</update_rate>
          <camera>
            <horizontal_fov>1.0472</horizontal_fov>
            <image>
              <width>640</width>
              <height>480</height>
              <format>R8G8B8</format>
            </image>
            <clip>
              <near>0.05</near>
              <far>3</far>
            </clip>
          </camera>
          <plugin name='camera_plugin' filename='libgazebo_ros_openni_kinect.so'>
            <baseline>0.2</baseline>
            <alwaysOn>1</alwaysOn>
            <updateRate>0.0</updateRate>
            <cameraName>camera_ir</cameraName>
            <imageTopicName>/camera2/color/image_raw</imageTopicName>
            <cameraInfoTopicName>/camera2/color/camera_info</cameraInfoTopicName>
            <depthImageTopicName>/camera2/depth/image_raw</depthImageTopicName>
            <depthImageCameraInfoTopicName>/camera2/depth/camera_info</depthImageCameraInfoTopicName>
            <pointCloudTopicName>/camera2/depth/points</pointCloudTopicName>
            <frameName>camera_link</frameName>
            <pointCloudCutoff>0.5</pointCloudCutoff>
            <pointCloudCutoffMax>3.0</pointCloudCutoffMax>
            <distortionK1>0</distortionK1>
            <distortionK2>0</distortionK2>
            <distortionK3>0</distortionK3>
            <distortionT1>0</distortionT1>
            <distortionT2>0</distortionT2>
            <CxPrime>0</CxPrime>
            <Cx>0</Cx>
            <Cy>0</Cy>
            <focalLength>0</focalLength>
            <hackBaseline>0</hackBaseline>
          </plugin>
        </sensor>
        <self_collide>0</self_collide>
        <enable_wind>0</enable_wind>
        <kinematic>0</kinematic>
        <pose>0 0 0 0 -0 0</pose>
        <visual name='visual'>
          <geometry>
            <mesh>
              <uri>model://kinect/meshes/kinect.dae</uri>
            </mesh>
          </geometry>
          <material>
            <shader type='pixel'/>
          </material>
          <pose>0 0 0 0 -0 0</pose>
          <transparency>0</transparency>
          <cast_shadows>1</cast_shadows>
        </visual>
        <collision name='collision'>
          <laser_retro>0</laser_retro>
          <max_contacts>10</max_contacts>
          <pose>0 0 0 0 -0 0</pose>
          <geometry>
            <box>
              <size>0.073 0.276 0.072</size>
            </box>
          </geometry>
          <surface>
            <friction>
              <ode>
                <mu>1</mu>
                <mu2>1</mu2>
                <fdir1>0 0 0</fdir1>
                <slip1>0</slip1>
                <slip2>0</slip2>
              </ode>
              <torsional>
                <coefficient>1</coefficient>
                <patch_radius>0</patch_radius>
                <surface_radius>0</surface_radius>
                <use_patch_radius>1</use_patch_radius>
                <ode>
                  <slip>0</slip>
                </ode>
              </torsional>
            </friction>
            <bounce>
              <restitution_coefficient>0</restitution_coefficient>
              <threshold>1e+06</threshold>
            </bounce>
            <contact>
              <collide_without_contact>0</collide_without_contact>
              <collide_without_contact_bitmask>1</collide_without_contact_bitmask>
              <collide_bitmask>1</collide_bitmask>
              <ode>
                <soft_cfm>0</soft_cfm>
                <soft_erp>0.2</soft_erp>
                <kp>1e+13</kp>
                <kd>1</kd>
                <max_vel>0.01</max_vel>
                <min_depth>0</min_depth>
              </ode>
              <bullet>
                <split_impulse>1</split_impulse>
                <split_impulse_penetration_threshold>-0.01</split_impulse_penetration_threshold>
                <soft_cfm>0</soft_cfm>
                <soft_erp>0.2</soft_erp>
                <kp>1e+13</kp>
                <kd>1</kd>
              </bullet>
            </contact>
          </surface>
        </collision>
      </link>
      <static>1</static>
      <allow_auto_disable>1</allow_auto_disable>
      <pose>0.137595 -0.794894 0.036005 -3.4e-05 -2e-06 -2e-06</pose>
    </model>
  </world>
</sdf>
